Workbook

Sheet LEIA-ME
B2: ⚠️ ATENÇÃO – LEIA ANTES DE USAR Esta planilha foi construída para que apenas uma aba seja editada: 👉 “Todas as Funções (Editável)” Todas as demais abas contêm fórmulas e vínculos automáticos. Não altere, não exclua e não renomeie abas, colunas ou fórmulas.
B4: Esta planilha permite a atualização da classificação das Funções Estratégicas sem necessidade de ajustes manuais em cálculos ou fórmulas. Siga rigorosamente as orientações abaixo. 1️⃣ Aba editável Existe apenas uma aba que pode ser editada: 👉 “Todas as Funções (Editável)” É nessa aba que se encontra a lista mais recente de funções mapeadas, construída a partir da coleta manual no SICI de todas as funções até o 3º escalão. 2️⃣ Atualizações estruturais (SICI) Caso haja atualização no SICI: A) De um Órgão já existente - Se apenas houver mudanças em atributos (Área, Escalão, Tipo de Cargo, Nome do Cargo), edite diretamente a linha correspondente. - Se surgirem novas áreas ou funções dentro do órgão, adicione novas linhas ao final das linhas. B) Se for um Órgão novo - Insira as informações das funções ao final da aba. - Verifique se alguma estrutura de órgão existente foi transferida para o novo órgão. - Caso positivo, edite ou exclua as linhas do órgão de origem, conforme o caso. C) Se um Órgão foi extinto Exclua todas as linhas referentes às funções daquele órgão. ⚠️ Importante: não crie novos padrões de nomenclatura. Utilize sempre os nomes institucionais consolidados. Veja o padrão observando outras linhas da tabela. 3️⃣ Preenchimento das colunas I a J Além das informações estruturais, é necessário preencher as colunas I a J, conforme descrito abaixo: - “Gere equipe”: Indica se o ocupante titular daquela função possui equipe sob sua gestão. - “Autonomia para ordenar despesa”: Indica se a função possui competência formal para ordenação de despesa. “Magnitude do Orçamento Gerido”: Deve ser preenchida com as opções 2 a 4 apenas para funções com competência para ordenação de despesa; e titulares de Pasta. Os demais devem ficar com 1. “Poder de decisão sobre o orçamento do órgão”: A resposta “sim” deve ser atribuída apenas às funções regulamentadas pelo RGCAF que possuem poder de decisão sobre a alocação orçamentária, ainda que nem todas atuem como ordenadores formais de despesa.
B6: Para conferir se sua atualização deu certo e a Função foi classificada, confira na coluna "Status da Classificação" da aba "Cálculo". Obs: Na aba "Cálculo" as linhas ou células que estão pintadas na cor amarelo são aquelas que estão com as funções que realizam a importação dos dados e os cálculos.
B8: A metodologia completa do Mapeamento de Funções Estratégicas está documentada em relatório próprio, elaborado pela CDC/FJG, e deve ser consultada em caso de dúvidas conceituais ou revisões metodológicas
B9: Relatório Metodológico do Mapeamento de Funções Estratégicas 2025

Sheet Todas as Funções (Editável)
A1: ID (automático) | B1: Órgão | C1: Escalão (como está na árvore do SICI) | D1: Área (como está no SICI) | E1: Nome do Cargo (como está no SICI) | F1: Tipo de Cargo (deve ser um dos oito tipos) | G1: Área de Negócio (referente à Área) | H1: Macro Área (referente ao órgão) | I1: Gere equipe | J1: Autonomia para ordenar despesa | K1: Magnitude do Orçamento Gerido (apenas para funções com competência para ordenação de despesa e Titulares de Pasta) | L1: Poder de Decisão sobre o Orçamento (funções regulamentadas pelo RGCAF que possuem poder de decisão sobre a alocação orçamentária, ainda que nem todas atuem como ordenadores formais de despesa) | M1: Titular
B2: GBP | C2: 1º | D2: Gabinete do Prefeito | E2: Coordenador Especial do Gabinete do Prefeito | F2: Coordenador(a) | G2: ⚠️ REVISÃO MANUAL (72.26% de Confiança): Técnico-Operacional | H2: Gestão | I2: 2 - Sim | J2: 1 - Não | L2: 1 - Não possui poder de decisão sobre alocação de recursos orçamentários no órgão | M2: Fernando de Menezes Duba
B3: GBP | C3: 2º | D3: Secretaria Geral do CompStat Municipal | E3: Secretário Geral | G3: Administrativo | H3: Gestão | J3: 2 - Sim | L3: 2 - Possui poder de decisão sobre alocação de recursos orçamentários no órgão | M3: Thiago Ramos Dias
B4: GBP | C4: 2º | D4: Assessoria Especial do Gabinete do Prefeito | E4: Assessor Chefe Técnico | F4: Assessor(a) | G4: ⚠️ REVISÃO MANUAL (72.26% de Confiança): Técnico-Operacional | H4: Gestão | I4: 2 - Sim | J4: 1 - Não | L4: 1 - Não possui poder de decisão sobre alocação de recursos orçamentários no órgão | M4: Eduardo Braga Goldenberg
B5: GBP | C5: 2º | D5: Assessoria Técnica de Assuntos Urbanísticos | E5: Assessor Chefe | F5: Assessor(a) | G5: Técnico-Operacional | H5: Gestão | I5: 2 - Sim | J5: 1 - Não | L5: 1 - Não possui poder de decisão sobre alocação de recursos orçamentários no órgão | M5: Maria Madalena Saint Martin de Astacio
B6: GBP | C6: 2º | D6: Assessoria Especial de Estratégia e Políticas Públicas | E6: Assessor Chefe | F6: Assessor(a) | G6: Técnico-Operacional | H6: Gestão | I6: 2 - Sim | J6: 1 - Não | L6: 1 - Não possui poder de decisão sobre alocação de recursos orçamentários no órgão | M6: Guilherme Victor Testoni Boisson
B7: GBP | C7: 2º | D7: Assessoria de Controle de Diligências | E7: Assessor Chefe | F7: Assessor(a) | G7: ⚠️ REVISÃO MANUAL (43.12% de Confiança): Administrativo | H7: Gestão | I7: 2 - Sim | J7: 1 - Não | L7: 1 - Não possui poder de decisão sobre alocação de recursos orçamentários no órgão | M7: Michelle Rodrigues Schinke
B8: GBP | C8: 2º | D8: Assessoria de Estratégias Digitais | E8: Assessor Chefe | F8: Assessor(a) | G8: ⚠️ REVISÃO MANUAL (32.17% de Confiança): Comunicação e Relacionamento com o Cidadão | H8: Gestão | I8: 2 - Sim | J8: 1 - Não | L8: 1 - Não possui poder de decisão sobre alocação de recursos orçamentários no órgão | M8: Lucas Calil Guimarães Silva
B9: GBP | C9: 2º | D9: Assessoria Técnica do Gabinete do Prefeito | E9: Assessor Chefe I | F9: Assessor(a) | G9: Técnico-Operacional | H9: Gestão | I9: 2 - Sim | J9: 1 - Não | L9: 1 - Não possui poder de decisão sobre alocação de recursos orçamentários no órgão | M9: Marcela Odette Ferreira Barboza
B10: GBP | C10: 2º | D10: Assessoria de Apoio Operacional do Gabinete do Prefeito | E10: Assessor Chefe I | F10: Assessor(a) | G10: Técnico-Operacional | H10: Gestão | I10: 2 - Sim | J10: 1 - Não | L10: 1 - Não possui poder de decisão sobre alocação de recursos orçamentários no órgão | M10: Ana Cristina Boldi Fernandes
B11: GBP | C11: 2º | D11: Centro de Operações e Resiliência | E11: Chefe Executivo de Resiliência e Operações | F11: Chefe | G11: Técnico-Operacional | H11: Gestão | I11: 2 - Sim | J11: 1 - Não | L11: 1 - Não possui poder de decisão sobre alocação de recursos orçamentários no órgão | M11: Thiago Curvello Pinto
B12: GBP | C12: 3º | D12: Assessoria de Planejamento e Resiliência | E12: Assessor Chefe | F12: Assessor(a) | G12: Técnico-Operacional | H12: Gestão | I12: 2 - Sim | J12: 1 - Não | L12: 1 - Não possui poder de decisão sobre alocação de recursos orçamentários no órgão | M12: Ana Carla Badaró Moreira Prado
B13: GBP | C13: 3º | D13: Assessoria de Comunicação | E13: Assessor Chefe I | F13: Assessor(a) | G13: Comunicação e Relacionamento com o Cidadão | H13: Gestão | I13: 2 - Sim | J13: 1 - Não | L13: 1 - Não possui poder de decisão sobre alocação de recursos orçamentários no órgão | M13: Leonardo da Silva Cantalice
B14: GBP | C14: 3º | D14: Coordenadoria Técnica de Infraestrutura e Logística | E14: Coordenador Técnico | F14: Coordenador(a) | G14: Administrativo | H14: Gestão | I14: 2 - Sim | J14: 2 - Sim | L14: 2 - Possui poder de decisão sobre alocação de recursos orçamentários no órgão | M14: Maíra Oliveira da Silva
B15: GBP | C15: 3º | D15: Coordenadoria Técnica de Inovação | E15: Coordenador Técnico | F15: Coordenador(a) | G15: Técnico-Operacional | H15: Gestão | I15: 2 - Sim | J15: 1 - Não | L15: 1 - Não possui poder de decisão sobre alocação de recursos orçamentários no órgão | M15: Alexandre Goldfeld Cardeman
... B55: CASA CIVIL | C55: 3º | D55: Coordenadoria de Capacitação e Desenvolvimento | E55: Coordenador I | F55: Coordenador(a) | G55: ⚠️ REVISÃO MANUAL (48.03% de Confiança): Tecnologias da Informação | H55: Gestão | I55: 2 - Sim | J55: 1 - Não | L55: 1 - Não possui poder de decisão sobre alocação de recursos orçamentários no órgão | M55: Rafael Ferreira da Costa Leite
B56: CASA CIVIL | C56: 3º | D56: Núcleo NudgeRio | E56: nan | G56: Técnico-Operacional | H56: Gestão | J56: 1 - Não | L56: 1 - Não possui poder de decisão sobre alocação de recursos orçamentários no órgão | M56: nan
B57: CASA CIVIL | C57: 3º | D57: Núcleo Hub21 | E57: nan | G57: Técnico-Operacional | H57: Gestão | J57: 1 - Não | L57: 1 - Não possui poder de decisão sobre alocação de recursos orçamentários no órgão | M57: nan
B58: CASA CIVIL | C58: 2º | D58: Central de Inteligência, Vigilância e Tecnologia de Apoio a Segurança Pública | E58: Chefe Executivo | F58: Chefe | G58: Técnico-Operacional | H58: Gestão | I58: 2 - Sim | J58: 2 - Sim | L58: 2 - Possui poder de decisão sobre alocação de recursos orçamentários no órgão | M58: Davi de Mattos Carreiro
B59: CASA CIVIL | C59: 3º | D59: Coordenadoria de Tecnologia e Dados | E59: Coordenador I | F59: Coordenador(a) | G59: ⚠️ REVISÃO MANUAL (74.91% de Confiança): Tecnologias da Informação | H59: Gestão | I59: 2 - Sim | J59: 1 - Não | L59: 1 - Não possui poder de decisão sobre alocação de recursos orçamentários no órgão | M59: Maria Eduarda Lacerda Couto
B60: CASA CIVIL | C60: 3º | D60: Coordenadoria de Monitoramento e Operações | E60: Coordenador I | F60: Coordenador(a) | G60: Técnico-Operacional | H60: Gestão | I60: 2 - Sim | J60: 1 - Não | L60: 1 - Não possui poder de decisão sobre alocação de recursos orçamentários no órgão | M60: José Mauricio de Brito Padrone
B61: CASA CIVIL | C61: 2º | D61: Subsecretaria de Transformação Digital e Cidade Inteligente | E61: Subsecretário | F61: Subsecretário(a) | G61: ⚠️ REVISÃO MANUAL (60.11% de Confiança): Tecnologias da Informação | H61: Gestão | I61: 2 - Sim | J61: 1 - Não | L61: 2 - Possui poder de decisão sobre alocação de recursos orçamentários no órgão | M61: Raquel Gonçalves Coimbra Flexa
B62: CASA CIVIL | C62: 3º | D62: Coordenadoria Técnica de Transformação Digital | E62: Coordenador Técnico | F62: Coordenador(a) | G62: ⚠️ REVISÃO MANUAL (62.37% de Confiança): Tecnologias da Informação | H62: Gestão | I62: 2 - Sim | J62: 1 - Não | L62: 1 - Não possui poder de decisão sobre alocação de recursos orçamentários no órgão | M62: Bruno Rainho Mendonça
B63: CASA CIVIL | C63: 3º | D63: Coordenadoria de Relacionamento com o Cidadão | E63: Coordenador I | F63: Coordenador(a) | G63: ⚠️ REVISÃO MANUAL (44.98% de Confiança): Tecnologias da Informação | H63: Gestão | I63: 2 - Sim | J63: 1 - Não | L63: 1 - Não possui poder de decisão sobre alocação de recursos orçamentários no órgão | M63: Gabriela Gervason Reis
B64: CASA CIVIL | C64: 3º | D64: Coordenadoria de Cidade Inteligente | E64: Coordenador I | F64: Coordenador(a) | G64: ⚠️ REVISÃO MANUAL (73.74% de Confiança): Tecnologias da Informação | H64: Gestão | I64: 2 - Sim | J64: 1 - Não | L64: 1 - Não possui poder de decisão sobre alocação de recursos orçamentários no órgão | M64: Willington Domingues Feitosa
B65: CASA CIVIL | C65: 2º | D65: Subsecretaria de Planejamento e Acompanhamento de Resultados | E65: Subsecretário | F65: Subsecretário(a) | G65: ⚠️ REVISÃO MANUAL (59.0% de Confiança): Administrativo | H65: Gestão | I65: 2 - Sim | J65: 2 - Sim | L65: 2 - Possui poder de decisão sobre alocação de recursos orçamentários no órgão | M65: Roberta de Oliveira Guimarães
B66: CASA CIVIL | C66: 3º | D66: Escritório de Planejamento | E66: Coordenador Geral | F66: Coordenador(a) | G66: Técnico-Operacional | H66: Gestão | I66: 2 - Sim | J66: 1 - Não | L66: 1 - Não possui poder de decisão sobre alocação de recursos orçamentários no órgão | M66: Daniel Gleidson Mancebo de Araujo
B67: CASA CIVIL | C67: 3º | D67: Escritório de Gerenciamento de Projetos e Metas | E67: Coordenador Geral | F67: Coordenador(a) | G67: Técnico-Operacional | H67: Gestão | I67: 2 - Sim | J67: 1 - Não | L67: 1 - Não possui poder de decisão sobre alocação de recursos orçamentários no órgão | M67: Fernanda Mofati Lanhas
B68: CASA CIVIL | C68: 2º | D68: Subsecretaria de Assuntos Institucionais | E68: Subsecretário | F68: Subsecretário(a) | G68: Administrativo | H68: Gestão | I68: 2 - Sim | J68: 2 - Sim | L68: 2 - Possui poder de decisão sobre alocação de recursos orçamentários no órgão | M68: Andre Luiz Faria Miranda
B69: CASA CIVIL | C69: 3º | D69: Núcleo de Assuntos Institucionais | E69: Gerente III | F69: Gerente | G69: ⚠️ REVISÃO MANUAL (54.14% de Confiança): Administrativo | H69: Gestão | I69: 2 - Sim | J69: 1 - Não | L69: 1 - Não possui poder de decisão sobre alocação de recursos orçamentários no órgão | M69: Breno Melaragno Costa
... B217: SMF | C217: 3º | D217: Gerência de Integração Governamental | E217: Gerente II | F217: Gerente | G217: Técnico-Operacional | H217: Gestão | I217: 2 - Sim | J217: 1 - Não | L217: 1 - Não possui poder de decisão sobre alocação de recursos orçamentários no órgão | M217: Marcus Vinicius Fraga Martins
B218: SMF | C218: 2º | D218: Núcleo de Apoio Técnico | E218: nan | G218: Técnico-Operacional | H218: Gestão | J218: 1 - Não | L218: 1 - Não possui poder de decisão sobre alocação de recursos orçamentários no órgão | M218: nan
B219: SMA | C219: 1º | D219: Secretaria Municipal de Administração | E219: Secretário Municipal | F219: Secretário(a) | G219: Administrativo | H219: Gestão | I219: 2 - Sim | J219: 2 - Sim | L219: 2 - Possui poder de decisão sobre alocação de recursos orçamentários no órgão | M219: Bernardo Egas Lima Fonseca
B220: SMA | C220: 2º | D220: Núcleo de Monitoramento e Indicadores | E220: Diretor IV | F220: Diretor(a) | G220: ⚠️ REVISÃO MANUAL (72.08% de Confiança): Técnico-Operacional | H220: Gestão | I220: 2 - Sim | J220: 1 - Não | L220: 1 - Não possui poder de decisão sobre alocação de recursos orçamentários no órgão | M220: Willians Cesar Rocha Gaspar
B221: SMA | C221: 2º | D221: Assessoria Técnica Administrativa | E221: Assessor Chefe | F221: Assessor(a) | G221: Administrativo | H221: Gestão | I221: 2 - Sim | J221: 1 - Não | L221: 1 - Não possui poder de decisão sobre alocação de recursos orçamentários no órgão | M221: Felipe de Freitas Lima Magalhães
B222: SMA | C222: 2º | D222: Assessoria de Comunicação Social | E222: Assessor Chefe I | F222: Assessor(a) | G222: Comunicação e Relacionamento com o Cidadão | H222: Gestão | I222: 2 - Sim | J222: 1 - Não | L222: 1 - Não possui poder de decisão sobre alocação de recursos orçamentários no órgão | M222: Deborah Moura Carrolo
B223: SMA | C223: 2º | D223: Ouvidoria | E223: Ouvidor | F223: Ouvidor(a) | G223: Comunicação e Relacionamento com o Cidadão | H223: Gestão | I223: 1 - Não | J223: 1 - Não | L223: 1 - Não possui poder de decisão sobre alocação de recursos orçamentários no órgão | M223: Janaina Mattos de Bacelar
B224: SMA | C224: 2º | D224: Subsecretaria do Sistema Municipal de Administração | E224: Subsecretário | F224: Subsecretário(a) | G224: Administrativo | H224: Gestão | I224: 2 - Sim | J224: 1 - Não | L224: 2 - Possui poder de decisão sobre alocação de recursos orçamentários no órgão | M224: Ana Paula da Silva Giesteira
B225: SMA | C225: 3º | D225: Coordenadoria Geral de Suprimentos e Infraestrutura | E225: Coordenador Geral | F225: Coordenador(a) | G225: ⚠️ REVISÃO MANUAL (32.69% de Confiança): Técnico-Operacional | H225: Gestão | I225: 2 - Sim | J225: 1 - Não | L225: 1 - Não possui poder de decisão sobre alocação de recursos orçamentários no órgão | M225: Alexandre Gonçalves de Souza
B226: SMA | C226: 3º | D226: Coordenadoria Geral de Recursos Humanos | E226: Coordenador Geral | F226: Coordenador(a) | G226: Administrativo | H226: Gestão | I226: 2 - Sim | J226: 2 - Sim | L226: 2 - Possui poder de decisão sobre alocação de recursos orçamentários no órgão | M226: Anderson Ferraz Carneiro
...

Sheet Notas Médias
A1: Escalão | B1: Área de Negócio | C1: Tipo de cargo | D1: Chave | E1: Necessidade de realizar articulação com atores | F1: Grau de visibilidade frente a apoio público e accountability | G1: Nível de autonomia para formular e executar políticas públicas | H1: Grau de conhecimento técnico/especializado | I1: Capacidade de ação da área na execução de suas atividades | J1: Capacidade de ação da área na elaboração de estratégias acordadas
A2: 1º | B2: Administrativo | C2: Chefe | D2: {=IF(A2:A985="",, A2:A985&"|"&B2:B985&"|"&C2:C985)} | E2: 4 | F2: 3 | G2: 3 | H2: 3 | I2: 3 | J2: 3
A3: 1º | B3: Administrativo | C3: Coordenador(a) | D3: 1º|Administrativo|Coordenador(a) | E3: 4 | F3: 3 | G3: 3 | H3: 3 | I3: 3 | J3: 3
A4: 1º | B4: Administrativo | C4: Presidente | D4: 1º|Administrativo|Presidente | E4: 4 | F4: 4 | G4: 4 | H4: 4 | I4: 4 | J4: 4
A5: 1º | B5: Administrativo | C5: Secretário(a) | D5: 1º|Administrativo|Secretário(a) | E5: 4 | F5: 3 | G5: 4 | H5: 3 | I5: 4 | J5: 4
A6: 2º | B6: Administrativo | C6: Assessor(a) | D6: 2º|Administrativo|Assessor(a) | E6: 2 | F6: 1 | G6: 1 | H6: 3 | I6: 2 | J6: 2
A7: 2º | B7: Administrativo | C7: Chefe | D7: 2º|Administrativo|Chefe | E7: 4 | F7: 2 | G7: 2 | H7: 3 | I7: 3 | J7: 3
A8: 2º | B8: Administrativo | C8: Coordenador(a) | D8: 2º|Administrativo|Coordenador(a) | E8: 3 | F8: 2 | G8: 2 | H8: 3 | I8: 3 | J8: 2
A9: 2º | B9: Administrativo | C9: Diretor(a) | D9: 2º|Administrativo|Diretor(a) | E9: 2 | F9: 2 | G9: 1 | H9: 3 | I9: 2 | J9: 1
A10: 2º | B10: Administrativo | C10: Presidente | D10: 2º|Administrativo|Presidente | E10: 4 | F10: 3 | G10: 4 | H10: 4 | I10: 4 | J10: 4
A11: 2º | B11: Administrativo | C11: Subsecretário(a) | D11: 2º|Administrativo|Subsecretário(a) | E11: 3 | F11: 3 | G11: 3 | H11: 3 | I11: 3 | J11: 3
A12: 2º | B12: Comunicação e Relacionamento com o Cidadão | C12: Assessor(a) | D12: 2º|Comunicação e Relacionamento com o Cidadão|Assessor(a) | E12: 3 | F12: 2 | G12: 1 | H12: 4 | I12: 2 | J12: 2
A13: 2º | B13: Comunicação e Relacionamento com o Cidadão | C13: Coordenador(a) | D13: 2º|Comunicação e Relacionamento com o Cidadão|Coordenador(a) | E13: 3 | F13: 3 | G13: 3 | H13: 4 | I13: 2 | J13: 2
A14: 2º | B14: Comunicação e Relacionamento com o Cidadão | C14: Ouvidor(a) | D14: 2º|Comunicação e Relacionamento com o Cidadão|Ouvidor(a) | E14: 2 | F14: 2 | G14: 1 | H14: 2 | I14: 2 | J14: 2
... A55: 3º | B55: Tecnologias da Informação | C55: Gerente | D55: 3º|Tecnologias da Informação|Gerente | E55: 2 | F55: 1 | G55: 2 | H55: 4 | I55: 2 | J55: 2
D56: 0
D57: 0
D58: 0
D59: 0
D60: 0
D61: 0
D62: 0
D63: 0
D64: 0
D65: 0
D66: 0
D67: 0
... D985: 0

Sheet Cargos Classificados na Reunião
A1: ID | B1: Órgão | C1: Escalão | D1: Nome do Cargo | E1: Tipo de cargo | F1: Área | G1: Área de Negócio | H1: Macro Área | I1: Necessidade de realizar articulação com atores | J1: Grau de visibilidade frente a apoio público e accountability | K1: RESPONSABILIDADE DE GERIR OUTRAS PESSOAS / EQUIPES | L1: AUTONOMIA PARA ORDENAR DESPESAS | M1: Nível de autonomia para formular e executar políticas públicas | N1: Grau de conhecimento técnico/especializado | O1: Capacidade de ação da área na execução de suas atividades | P1: Capacidade de ação da área na elaboração de estratégias acordadas | Q1: MAGNITUDE DO ORÇAMENTO gerido pelo ocupante do cargo | R1: PODER DE DECISÃO sobre alocação de ORÇAMENTO no órgão
A2: 1001 | B2: SMF | C2: 1º | D2: Secretário Municipal | E2: Secretário(a) | F2: Secretaria Municipal de Fazenda | G2: Administrativo | H2: Gestão | I2: 3 | J2: 4 | M2: 4 | N2: 4 | O2: 4 | P2: 4
A3: 1098 | B3: SMG | C3: 1º | D3: Secretário Municipal | E3: Secretário(a) | F3: Secretaria Municipal de Governo | G3: Administrativo | H3: Gestão | I3: 4 | J3: 4 | M3: 4 | N3: 3 | O3: 4 | P3: 4
A4: 165 | B4: CGM | C4: 2º | D4: Assessor Chefe Técnico | E4: Assessor(a) | F4: Assessoria Técnica do Gabinete | G4: Técnico-Operacional | H4: Gestão | I4: 2 | J4: 2 | M4: 2 | N4: 3 | O4: 3 | P4: 2
A5: 168 | B5: CGM | C5: 2º | D5: Subcontrolador | E5: Subsecretário(a) | F5: Subcontroladoria de Auditoria e Controle | G5: Jurídico | H5: Gestão | I5: 2 | J5: 2 | M5: 3 | N5: 4 | O5: 4 | P5: 4
A6: 169 | B6: CGM | C6: 3º | D6: Auditor Geral | E6: Coordenador(a) | F6: Auditoria Geral | G6: Jurídico | H6: Gestão | I6: 1 | J6: 3 | M6: 3 | N6: 4 | O6: 4 | P6: 4
A7: 171 | B7: CGM | C7: 3º | D7: Coordenador Técnico | E7: Coordenador(a) | F7: Coordenadoria Técnica de Controles e Normas | G7: Técnico-Operacional | H7: Gestão | I7: 3 | J7: 3 | M7: 3 | N7: 4 | O7: 3 | P7: 2
A8: 172 | B8: CGM | C8: 2º | D8: Subcontrolador | E8: Subsecretário(a) | F8: Subcontroladoria de Contabilidade | G8: Financeiro | H8: Gestão | I8: 2 | J8: 3 | M8: 3 | N8: 4 | O8: 4 | P8: 4
A9: 175 | B9: CGM | C9: 3º | D9: Coordenador I | E9: Coordenador(a) | F9: Coordenadoria de Monitoramento e Controle da Regularidade Fiscal | G9: Técnico-Operacional | H9: Gestão | I9: 2 | J9: 4 | M9: 3 | N9: 4 | O9: 4 | P9: 4
A10: 259 | B10: PGM | C10: 2º | D10: Ouvidor de Núcleo I | E10: Ouvidor(a) | F10: Núcleo de Ouvidoria I | G10: Comunicação e Relacionamento com o Cidadão | H10: Gestão | I10: 4 | J10: 1 | M10: 2 | N10: 2 | O10: 3 | P10: 2
A11: 261 | B11: PGM | C11: 2º | D11: Subprocurador Geral do Município | E11: Subsecretário(a) | F11: Subprocuradoria Geral Judicial | G11: Jurídico | H11: Gestão | I11: 4 | J11: 2 | M11: 3 | N11: 4 | O11: 4 | P11: 4
A12: 264 | B12: PGM | C12: 3º | D12: Gerente III | E12: Gerente | F12: Gerência de Gestão de Ofícios | G12: Técnico-Operacional | H12: Gestão | I12: 4 | J12: 2 | M12: 2 | N12: 2 | O12: 3 | P12: 3
A13: 267 | B13: PGM | C13: 2º | D13: Procurador Chefe | E13: Diretor(a) | F13: Procuradoria de Dívida Ativa | G13: Jurídico | H13: Gestão | I13: 3 | J13: 3 | M13: 3 | N13: 4 | O13: 4 | P13: 4
... A1025: 937 | B1025: SMS | C1025: 3º | D1025: Coordenador Geral | E1025: Coordenador(a) | F1025: Coordenadoria Geral de Contratualização, Controle e Auditoria | G1025: Administrativo | H1025: Social | I1025: 2 | J1025: 2 | M1025: 1 | N1025: 4 | O1025: 2 | P1025: 2
A1026: 938 | B1026: SMS | C1026: 3º | D1026: Coordenador Geral | E1026: Coordenador(a) | F1026: Coordenadoria Geral do Complexo Regulador | G1026: Técnico-Operacional | H1026: Social | I1026: 4 | J1026: 4 | N1026: 4 | O1026: 4 | P1026: 4
A1027: 1066 | B1027: SMDU | C1027: 1º | D1027: Secretário Municipal | E1027: Secretário(a) | F1027: Secretaria Municipal de Desenvolvimento Urbano e Licenciamento | G1027: Administrativo | H1027: Planejamento Urbano e Econômico | I1027: 4 | J1027: 4 | M1027: 4 | N1027: 3 | O1027: 4 | P1027: 4
A1028: 1071 | B1028: SMDU | C1028: 2º | D1028: Subsecretário | E1028: Subsecretário(a) | F1028: Subsecretaria de Planejamento Urbano | G1028: Técnico-Operacional | H1028: Planejamento Urbano e Econômico | I1028: 4 | J1028: 3 | M1028: 3 | N1028: 4 | O1028: 4 | P1028: 4
A1029: 1072 | B1029: SMDU | C1029: 3º | D1029: Coordenador Técnico | E1029: Coordenador(a) | F1029: Coordenadoria Técnica de Planejamento Urbano | G1029: Técnico-Operacional | H1029: Planejamento Urbano e Econômico | I1029: 3 | J1029: 3 | M1029: 2 | N1029: 4 | O1029: 3 | P1029: 3
A1030: 1073 | B1030: SMDU | C1030: 3º | D1030: Coordenador I | E1030: Coordenador(a) | F1030: Coordenadoria de Estudos Urbanos | G1030: Técnico-Operacional | H1030: Planejamento Urbano e Econômico | I1030: 3 | J1030: 2 | M1030: 2 | N1030: 4 | O1030: 3 | P1030: 3
A1031: 1074 | B1031: SMDU | C1031: 3º | D1031: Coordenador I | E1031: Coordenador(a) | F1031: Coordenadoria de Planejamento Territorial | G1031: Técnico-Operacional | H1031: Planejamento Urbano e Econômico | I1031: 3 | J1031: 2 | M1031: 2 | N1031: 4 | O1031: 3 | P1031: 3
A1032: 1075 | B1032: SMDU | C1032: 3º | D1032: Coordenador I | E1032: Coordenador(a) | F1032: Coordenação de Projetos Urbanos | G1032: Técnico-Operacional | H1032: Planejamento Urbano e Econômico | I1032: 3 | J1032: 2 | M1032: 2 | N1032: 4 | O1032: 3 | P1032: 3
A1033: 1076 | B1033: SMDU | C1033: 2º | D1033: Subsecretário | E1033: Subsecretário(a) | F1033: Subsecretaria de Controle e Licenciamento Urbanístico | G1033: Técnico-Operacional | H1033: Planejamento Urbano e Econômico | I1033: 4 | J1033: 3 | M1033: 3 | N1033: 4 | O1033: 4 | P1033: 4
A1034: 1077 | B1034: SMDU | C1034: 3º | D1034: Coordenador Geral | E1034: Coordenador(a) | F1034: Coordenadoria Geral de Licenciamento e Fiscalização | G1034: Técnico-Operacional | H1034: Planejamento Urbano e Econômico | I1034: 3 | J1034: 3 | M1034: 2 | N1034: 4 | O1034: 3 | P1034: 4
A1035: 1078 | B1035: SMDU | C1035: 3º | D1035: Coordenador I | E1035: Coordenador(a) | F1035: Coordenadoria de Arrecadação Urbanística | G1035: Técnico-Operacional | H1035: Planejamento Urbano e Econômico | I1035: 3 | J1035: 2 | M1035: 1 | N1035: 3 | O1035: 3 | P1035: 3
A1036: 1079 | B1036: SMDU | C1036: 2º | D1036: Subsecretário | E1036: Subsecretário(a) | F1036: Subsecretaria de Controle e Licenciamento Ambiental | G1036: Técnico-Operacional | H1036: Planejamento Urbano e Econômico | I1036: 4 | J1036: 3 | M1036: 3 | N1036: 4 | O1036: 4 | P1036: 4
A1037: 1080 | B1037: SMDU | C1037: 3º | D1037: Coordenador I | E1037: Coordenador(a) | F1037: Coordenadoria de Controle Ambiental de Atividades de Serviços e Industriais | G1037: Técnico-Operacional | H1037: Planejamento Urbano e Econômico | I1037: 3 | J1037: 2 | M1037: 2 | N1037: 4 | O1037: 3 | P1037: 3
A1038: 1081 | B1038: SMDU | C1038: 3º | D1038: Coordenador I | E1038: Coordenador(a) | F1038: Coordenadoria de Controle Ambiental de Obras e Parcelamento do Solo | G1038: Técnico-Operacional | H1038: Planejamento Urbano e Econômico | I1038: 3 | J1038: 3 | M1038: 2 | N1038: 4 | O1038: 3 | P1038: 3
... A1164: 830 | B1164: SMTE | C1164: 3º | D1164: Gerente II | E1164: Gerente | F1164: Gerência de Projetos Especiais, Inovação e Novos Negócios | G1164: Técnico-Operacional | H1164: Social | I1164: 4 | J1164: 1 | M1164: 2 | N1164: 3 | O1164: 3 | P1164: 3

Sheet Cálculo
A1: =IFERROR(__xludf.dummyfunction("QUERY('Todas as Funções (Editável)'!A1:H3501, ""select A,B,C,D,E,F,G,H where A is not null"")"),"ID (automático)") | B1: =IFERROR(__xludf.dummyfunction("""COMPUTED_VALUE"""),"Órgão") | C1: =IFERROR(__xludf.dummyfunction("""COMPUTED_VALUE"""),"Escalão (como está na árvore do SICI)") | D1: =IFERROR(__xludf.dummyfunction("""COMPUTED_VALUE"""),"Área (como está no SICI)") | E1: =IFERROR(__xludf.dummyfunction("""COMPUTED_VALUE"""),"Nome do Cargo (como está no SICI)") | F1: =IFERROR(__xludf.dummyfunction("""COMPUTED_VALUE"""),"Tipo de Cargo (deve ser um dos oito tipos)") | G1: =IFERROR(__xludf.dummyfunction("""COMPUTED_VALUE"""),"Área de Negócio (referente à Área)") | H1: =IFERROR(__xludf.dummyfunction("""COMPUTED_VALUE"""),"Macro Área (referente ao órgão)") | I1: Necessidade de realizar articulação com atores | J1: Grau de visibilidade frente a apoio público e accountability | K1: Nível de autonomia para formular e executar políticas públicas | L1: Grau de conhecimento técnico/especializado | M1: Capacidade de ação da área na execução de suas atividades | N1: Capacidade de ação da área na elaboração de estratégias acordadas | O1: Gerencia equipe | P1: Autonomia para ordenar despesa | Q1: Magnitude do Orçamento Gerido | R1: Poder de Decisão sobre o Orçamento | S1: Pontos da Habilidade Política | T1: Requer Habilidade Política | U1: Pontos Habilidade Técnica | V1: Requer Habilidade Técnica | W1: Pontos Policy Making | X1: Requer Policy Making | Y1: Pontos Habilidade Gerencial | Z1: Requer Habilidade Gerencial | AA1: Pontos Responsabilidade Orçamentária | AB1: Requer Responsabilidade Orçamentária | AC1: Tipo estratégico (cálculo intermediário) | AD1: Nível estratégico | AE1: Status da classificação
A2: =IFERROR(__xludf.dummyfunction("""COMPUTED_VALUE"""),1) | B2: =IFERROR(__xludf.dummyfunction("""COMPUTED_VALUE"""),"GVP") | C2: =IFERROR(__xludf.dummyfunction("""COMPUTED_VALUE"""),"1º") | D2: =IFERROR(__xludf.dummyfunction("""COMPUTED_VALUE"""),"Gabinete do Vice-Prefeito") | E2: =IFERROR(__xludf.dummyfunction("""COMPUTED_VALUE"""),"Chefe de Gabinete") | F2: =IFERROR(__xludf.dummyfunction("""COMPUTED_VALUE"""),"Chefe") | G2: =IFERROR(__xludf.dummyfunction("""COMPUTED_VALUE"""),"Administrativo") | H2: =IFERROR(__xludf.dummyfunction("""COMPUTED_VALUE"""),"Gestão") | I2: {=map( C2:C2005, G2:G2005, F2:F2005, lambda(escal, area, tipo, IF( escal="", , xlookup( TRIM(escal)&"|"&TRIM(area)&"|"&TRIM(tipo), 'Notas Médias'!D:D, 'Notas Médias'!E:J, "" ) ) ) )} | J2: #NAME? | K2: #NAME? | L2: #NAME? | M2: #NAME? | N2: #NAME? | O2: {=LEFT('Todas as Funções (Editável)'!I2:I2005,1)} | P2: {=LEFT('Todas as Funções (Editável)'!J2:J2005,1)} | Q2: {=LEFT('Todas as Funções (Editável)'!K2:K2005,1)} | R2: {=LEFT('Todas as Funções (Editável)'!L2:L2005,1)} | S2: {=IF(I2:I2005="",, I2:I2005*J2:J2005)} | T2: {=IF(S2:S2005="",, IF(S2:S2005>=8,"Sim","Não"))} | U2: {=IF(K2:K2005="",, K2:K2005*L2:L2005)} | V2: {=IF(U2:U2005="",, IF(U2:U2005>=8,"Sim","Não"))} | W2: {=IF(M2:M2005="",, M2:M2005*N2:N2005)} | X2: {=IF( W2:W2005="", , IF( W2:W2005>=9, "Alta", IF( W2:W2005<4, "Baixa", "Média" ) ) )} | Y2: {=IF(O2:O2005="",, O2:O2005*P2:P2005)} | Z2: {=IF(Y2:Y2005="",, IF(Y2:Y2005>=2,"Sim","Não"))} | AA2: {=IF(Q2:Q2005="",, Q2:Q2005*R2:R2005)} | AB2: {=IF( AA2:AA2005="", , IF( AA2:AA2005>=4, "Alta", IF( AA2:AA2005<2, "Baixa", "Média" ) ) )} | AC2: {=IF( (F2:F2005="") + (R2:R2005=""), "", IFERROR( VLOOKUP( T2:T2005&Z2:Z2005&V2:V2005&X2:X2005&AB2:AB2005, premissas_tipo_cargo, 2, FALSE() ), "" ) )} | AD2: {=IFERROR(ifs( F2 = "Secretário(a)", INDEX(Secretario, MATCH(RIGHT(AC2), premissas_nivel_cargo_letra, 0), MATCH(VALUE(LEFT(AC2)), premissas_nivel_cargo_numero, 0)), F2 = "Presidente", INDEX(Presidente, MATCH(RIGHT(AC2), premissas_nivel_cargo_letra, 0), MATCH(VALUE(LEFT(AC2)), premissas_nivel_cargo_numero, 0)), F2 = "Subsecretário(a)", INDEX(Subsecretario, MATCH(RIGHT(AC2), premissas_nivel_cargo_letra, 0), MATCH(VALUE(LEFT(AC2)), premissas_nivel_cargo_numero, 0)), F2 = "Superintendente", INDEX(Superintendente, MATCH(RIGHT(AC2), premissas_nivel_cargo_letra, 0), MATCH(VALUE(LEFT(AC2)), premissas_nivel_cargo_numero, 0)), F2 = "Coordenador(a)", INDEX(Coordenador, MATCH(RIGHT(AC2), premissas_nivel_cargo_letra, 0), MATCH(VALUE(LEFT(AC2)), premissas_nivel_cargo_numero, 0)), F2 = "Chefe", INDEX(Chefe, MATCH(RIGHT(AC2), premissas_nivel_cargo_letra, 0), MATCH(VALUE(LEFT(AC2)), premissas_nivel_cargo_numero, 0)), F2 = "Diretor(a)", INDEX(Diretor, MATCH(RIGHT(AC2), premissas_nivel_cargo_letra, 0), MATCH(VALUE(LEFT(AC2)), premissas_nivel_cargo_numero, 0)), F2 = "Gerente", INDEX(Gerente, MATCH(RIGHT(AC2), premissas_nivel_cargo_letra, 0), MATCH(VALUE(LEFT(AC2)), premissas_nivel_cargo_numero, 0)), F2 = "Assessor(a)", INDEX(Assessor, MATCH(RIGHT(AC2), premissas_nivel_cargo_letra, 0), MATCH(VALUE(LEFT(AC2)), premissas_nivel_cargo_numero, 0)), F2 = "Ouvidor(a)", INDEX(Ouvidor, MATCH(RIGHT(AC2), premissas_nivel_cargo_letra, 0), MATCH(VALUE(LEFT(AC2)), premissas_nivel_cargo_numero, 0)) ), "")} | AE2: =ifs(G2 = "", "", AD2 = "", "Ainda Não Classificado", NOT(AD2 = ""), "Classificado com Sucesso")
A3: =IFERROR(__xludf.dummyfunction("""COMPUTED_VALUE"""),2) | B3: =IFERROR(__xludf.dummyfunction("""COMPUTED_VALUE"""),"GVP") | C3: =IFERROR(__xludf.dummyfunction("""COMPUTED_VALUE"""),"2º") | D3: =IFERROR(__xludf.dummyfunction("""COMPUTED_VALUE"""),"Coordenadoria de Imprensa") | E3: =IFERROR(__xludf.dummyfunction("""COMPUTED_VALUE"""),"Coordenador I") | F3: =IFERROR(__xludf.dummyfunction("""COMPUTED_VALUE"""),"Coordenador(a)") | G3: =IFERROR(__xludf.dummyfunction("""COMPUTED_VALUE"""),"Comunicação e Relacionamento com o Cidadão") | H3: =IFERROR(__xludf.dummyfunction("""COMPUTED_VALUE"""),"Gestão") | I3: #NAME? | J3: #NAME? | K3: #NAME? | L3: #NAME? | M3: #NAME? | N3: #NAME? | S3: #NAME? | T3: #NAME? | U3: #NAME? | V3: #NAME? | W3: #NAME? | X3: #NAME? | Y3: 0 | Z3: Não | AA3: 0 | AB3: Baixa | AD3: {=IFERROR(ifs( F3 = "Secretário(a)", INDEX(Secretario, MATCH(RIGHT(AC3), premissas_nivel_cargo_letra, 0), MATCH(VALUE(LEFT(AC3)), premissas_nivel_cargo_numero, 0)), F3 = "Presidente", INDEX(Presidente, MATCH(RIGHT(AC3), premissas_nivel_cargo_letra, 0), MATCH(VALUE(LEFT(AC3)), premissas_nivel_cargo_numero, 0)), F3 = "Subsecretário(a)", INDEX(Subsecretario, MATCH(RIGHT(AC3), premissas_nivel_cargo_letra, 0), MATCH(VALUE(LEFT(AC3)), premissas_nivel_cargo_numero, 0)), F3 = "Superintendente", INDEX(Superintendente, MATCH(RIGHT(AC3), premissas_nivel_cargo_letra, 0), MATCH(VALUE(LEFT(AC3)), premissas_nivel_cargo_numero, 0)), F3 = "Coordenador(a)", INDEX(Coordenador, MATCH(RIGHT(AC3), premissas_nivel_cargo_letra, 0), MATCH(VALUE(LEFT(AC3)), premissas_nivel_cargo_numero, 0)), F3 = "Chefe", INDEX(Chefe, MATCH(RIGHT(AC3), premissas_nivel_cargo_letra, 0), MATCH(VALUE(LEFT(AC3)), premissas_nivel_cargo_numero, 0)), F3 = "Diretor(a)", INDEX(Diretor, MATCH(RIGHT(AC3), premissas_nivel_cargo_letra, 0), MATCH(VALUE(LEFT(AC3)), premissas_nivel_cargo_numero, 0)), F3 = "Gerente", INDEX(Gerente, MATCH(RIGHT(AC3), premissas_nivel_cargo_letra, 0), MATCH(VALUE(LEFT(AC3)), premissas_nivel_cargo_numero, 0)), F3 = "Assessor(a)", INDEX(Assessor, MATCH(RIGHT(AC3), premissas_nivel_cargo_letra, 0), MATCH(VALUE(LEFT(AC3)), premissas_nivel_cargo_numero, 0)), F3 = "Ouvidor(a)", INDEX(Ouvidor, MATCH(RIGHT(AC3), premissas_nivel_cargo_letra, 0), MATCH(VALUE(LEFT(AC3)), premissas_nivel_cargo_numero, 0)) ), "")} | AE3: =ifs(G3 = "", "", AD3 = "", "Ainda Não Classificado", NOT(AD3 = ""), "Classificado com Sucesso")
A4: =IFERROR(__xludf.dummyfunction("""COMPUTED_VALUE"""),3) | B4: =IFERROR(__xludf.dummyfunction("""COMPUTED_VALUE"""),"GVP") | C4: =IFERROR(__xludf.dummyfunction("""COMPUTED_VALUE"""),"2º") | D4: =IFERROR(__xludf.dummyfunction("""COMPUTED_VALUE"""),"Coordenadoria de Comunicação Institucional") | E4: =IFERROR(__xludf.dummyfunction("""COMPUTED_VALUE"""),"Coordenador I") | F4: =IFERROR(__xludf.dummyfunction("""COMPUTED_VALUE"""),"Coordenador(a)") | G4: =IFERROR(__xludf.dummyfunction("""COMPUTED_VALUE"""),"Comunicação e Relacionamento com o Cidadão") | H4: =IFERROR(__xludf.dummyfunction("""COMPUTED_VALUE"""),"Gestão") | I4: #NAME? | J4: #NAME? | K4: #NAME? | L4: #NAME? | M4: #NAME? | N4: #NAME? | S4: #NAME? | T4: #NAME? | U4: #NAME? | V4: #NAME? | W4: #NAME? | X4: #NAME? | Y4: 0 | Z4: Não | AA4: 0 | AB4: Baixa | AD4: {=IFERROR(ifs( F4 = "Secretário(a)", INDEX(Secretario, MATCH(RIGHT(AC4), premissas_nivel_cargo_letra, 0), MATCH(VALUE(LEFT(AC4)), premissas_nivel_cargo_numero, 0)), F4 = "Presidente", INDEX(Presidente, MATCH(RIGHT(AC4), premissas_nivel_cargo_letra, 0), MATCH(VALUE(LEFT(AC4)), premissas_nivel_cargo_numero, 0)), F4 = "Subsecretário(a)", INDEX(Subsecretario, MATCH(RIGHT(AC4), premissas_nivel_cargo_letra, 0), MATCH(VALUE(LEFT(AC4)), premissas_nivel_cargo_numero, 0)), F4 = "Superintendente", INDEX(Superintendente, MATCH(RIGHT(AC4), premissas_nivel_cargo_letra, 0), MATCH(VALUE(LEFT(AC4)), premissas_nivel_cargo_numero, 0)), F4 = "Coordenador(a)", INDEX(Coordenador, MATCH(RIGHT(AC4), premissas_nivel_cargo_letra, 0), MATCH(VALUE(LEFT(AC4)), premissas_nivel_cargo_numero, 0)), F4 = "Chefe", INDEX(Chefe, MATCH(RIGHT(AC4), premissas_nivel_cargo_letra, 0), MATCH(VALUE(LEFT(AC4)), premissas_nivel_cargo_numero, 0)), F4 = "Diretor(a)", INDEX(Diretor, MATCH(RIGHT(AC4), premissas_nivel_cargo_letra, 0), MATCH(VALUE(LEFT(AC4)), premissas_nivel_cargo_numero, 0)), F4 = "Gerente", INDEX(Gerente, MATCH(RIGHT(AC4), premissas_nivel_cargo_letra, 0), MATCH(VALUE(LEFT(AC4)), premissas_nivel_cargo_numero, 0)), F4 = "Assessor(a)", INDEX(Assessor, MATCH(RIGHT(AC4), premissas_nivel_cargo_letra, 0), MATCH(VALUE(LEFT(AC4)), premissas_nivel_cargo_numero, 0)), F4 = "Ouvidor(a)", INDEX(Ouvidor, MATCH(RIGHT(AC4), premissas_nivel_cargo_letra, 0), MATCH(VALUE(LEFT(AC4)), premissas_nivel_cargo_numero, 0)) ), "")} | AE4: =ifs(G4 = "", "", AD4 = "", "Ainda Não Classificado", NOT(AD4 = ""), "Classificado com Sucesso")
A5: =IFERROR(__xludf.dummyfunction("""COMPUTED_VALUE"""),4) | B5: =IFERROR(__xludf.dummyfunction("""COMPUTED_VALUE"""),"GVP") | C5: =IFERROR(__xludf.dummyfunction("""COMPUTED_VALUE"""),"2º") | D5: =IFERROR(__xludf.dummyfunction("""COMPUTED_VALUE"""),"Coordenadoria de Conteúdo") | E5: =IFERROR(__xludf.dummyfunction("""COMPUTED_VALUE"""),"Coordenador I") | F5: =IFERROR(__xludf.dummyfunction("""COMPUTED_VALUE"""),"Coordenador(a)") | G5: =IFERROR(__xludf.dummyfunction("""COMPUTED_VALUE"""),"Comunicação e Relacionamento com o Cidadão") | H5: =IFERROR(__xludf.dummyfunction("""COMPUTED_VALUE"""),"Gestão") | I5: #NAME? | J5: #NAME? | K5: #NAME? | L5: #NAME? | M5: #NAME? | N5: #NAME? | S5: #NAME? | T5: #NAME? | U5: #NAME? | V5: #NAME? | W5: #NAME? | X5: #NAME? | Y5: 0 | Z5: Não | AA5: 0 | AB5: Baixa | AD5: {=IFERROR(ifs( F5 = "Secretário(a)", INDEX(Secretario, MATCH(RIGHT(AC5), premissas_nivel_cargo_letra, 0), MATCH(VALUE(LEFT(AC5)), premissas_nivel_cargo_numero, 0)), F5 = "Presidente", INDEX(Presidente, MATCH(RIGHT(AC5), premissas_nivel_cargo_letra, 0), MATCH(VALUE(LEFT(AC5)), premissas_nivel_cargo_numero, 0)), F5 = "Subsecretário(a)", INDEX(Subsecretario, MATCH(RIGHT(AC5), premissas_nivel_cargo_letra, 0), MATCH(VALUE(LEFT(AC5)), premissas_nivel_cargo_numero, 0)), F5 = "Superintendente", INDEX(Superintendente, MATCH(RIGHT(AC5), premissas_nivel_cargo_letra, 0), MATCH(VALUE(LEFT(AC5)), premissas_nivel_cargo_numero, 0)), F5 = "Coordenador(a)", INDEX(Coordenador, MATCH(RIGHT(AC5), premissas_nivel_cargo_letra, 0), MATCH(VALUE(LEFT(AC5)), premissas_nivel_cargo_numero, 0)), F5 = "Chefe", INDEX(Chefe, MATCH(RIGHT(AC5), premissas_nivel_cargo_letra, 0), MATCH(VALUE(LEFT(AC5)), premissas_nivel_cargo_numero, 0)), F5 = "Diretor(a)", INDEX(Diretor, MATCH(RIGHT(AC5), premissas_nivel_cargo_letra, 0), MATCH(VALUE(LEFT(AC5)), premissas_nivel_cargo_numero, 0)), F5 = "Gerente", INDEX(Gerente, MATCH(RIGHT(AC5), premissas_nivel_cargo_letra, 0), MATCH(VALUE(LEFT(AC5)), premissas_nivel_cargo_numero, 0)), F5 = "Assessor(a)", INDEX(Assessor, MATCH(RIGHT(AC5), premissas_nivel_cargo_letra, 0), MATCH(VALUE(LEFT(AC5)), premissas_nivel_cargo_numero, 0)), F5 = "Ouvidor(a)", INDEX(Ouvidor, MATCH(RIGHT(AC5), premissas_nivel_cargo_letra, 0), MATCH(VALUE(LEFT(AC5)), premissas_nivel_cargo_numero, 0)) ), "")} | AE5: =ifs(G5 = "", "", AD5 = "", "Ainda Não Classificado", NOT(AD5 = ""), "Classificado com Sucesso")
A6: =IFERROR(__xludf.dummyfunction("""COMPUTED_VALUE"""),5) | B6: =IFERROR(__xludf.dummyfunction("""COMPUTED_VALUE"""),"GVP") | C6: =IFERROR(__xludf.dummyfunction("""COMPUTED_VALUE"""),"2º") | D6: =IFERROR(__xludf.dummyfunction("""COMPUTED_VALUE"""),"Coordenadoria de Integração Territorial") | E6: =IFERROR(__xludf.dummyfunction("""COMPUTED_VALUE"""),"Coordenador I") | F6: =IFERROR(__xludf.dummyfunction("""COMPUTED_VALUE"""),"Coordenador(a)") | G6: =IFERROR(__xludf.dummyfunction("""COMPUTED_VALUE"""),"Técnico-Operacional") | H6: =IFERROR(__xludf.dummyfunction("""COMPUTED_VALUE"""),"Gestão") | I6: #NAME? | J6: #NAME? | K6: #NAME? | L6: #NAME? | M6: #NAME? | N6: #NAME? | S6: #NAME? | T6: #NAME? | U6: #NAME? | V6: #NAME? | W6: #NAME? | X6: #NAME? | Y6: 0 | Z6: Não | AA6: 0 | AB6: Baixa | AD6: {=IFERROR(ifs( F6 = "Secretário(a)", INDEX(Secretario, MATCH(RIGHT(AC6), premissas_nivel_cargo_letra, 0), MATCH(VALUE(LEFT(AC6)), premissas_nivel_cargo_numero, 0)), F6 = "Presidente", INDEX(Presidente, MATCH(RIGHT(AC6), premissas_nivel_cargo_letra, 0), MATCH(VALUE(LEFT(AC6)), premissas_nivel_cargo_numero, 0)), F6 = "Subsecretário(a)", INDEX(Subsecretario, MATCH(RIGHT(AC6), premissas_nivel_cargo_letra, 0), MATCH(VALUE(LEFT(AC6)), premissas_nivel_cargo_numero, 0)), F6 = "Superintendente", INDEX(Superintendente, MATCH(RIGHT(AC6), premissas_nivel_cargo_letra, 0), MATCH(VALUE(LEFT(AC6)), premissas_nivel_cargo_numero, 0)), F6 = "Coordenador(a)", INDEX(Coordenador, MATCH(RIGHT(AC6), premissas_nivel_cargo_letra, 0), MATCH(VALUE(LEFT(AC6)), premissas_nivel_cargo_numero, 0)), F6 = "Chefe", INDEX(Chefe, MATCH(RIGHT(AC6), premissas_nivel_cargo_letra, 0), MATCH(VALUE(LEFT(AC6)), premissas_nivel_cargo_numero, 0)), F6 = "Diretor(a)", INDEX(Diretor, MATCH(RIGHT(AC6), premissas_nivel_cargo_letra, 0), MATCH(VALUE(LEFT(AC6)), premissas_nivel_cargo_numero, 0)), F6 = "Gerente", INDEX(Gerente, MATCH(RIGHT(AC6), premissas_nivel_cargo_letra, 0), MATCH(VALUE(LEFT(AC6)), premissas_nivel_cargo_numero, 0)), F6 = "Assessor(a)", INDEX(Assessor, MATCH(RIGHT(AC6), premissas_nivel_cargo_letra, 0), MATCH(VALUE(LEFT(AC6)), premissas_nivel_cargo_numero, 0)), F6 = "Ouvidor(a)", INDEX(Ouvidor, MATCH(RIGHT(AC6), premissas_nivel_cargo_letra, 0), MATCH(VALUE(LEFT(AC6)), premissas_nivel_cargo_numero, 0)) ), "")} | AE6: =ifs(G6 = "", "", AD6 = "", "Ainda Não Classificado", NOT(AD6 = ""), "Classificado com Sucesso")
A7: =IFERROR(__xludf.dummyfunction("""COMPUTED_VALUE"""),6) | B7: =IFERROR(__xludf.dummyfunction("""COMPUTED_VALUE"""),"GVP") | C7: =IFERROR(__xludf.dummyfunction("""COMPUTED_VALUE"""),"2º") | D7: =IFERROR(__xludf.dummyfunction("""COMPUTED_VALUE"""),"Coordenadoria Executiva") | E7: =IFERROR(__xludf.dummyfunction("""COMPUTED_VALUE"""),"Coordenador I") | F7: =IFERROR(__xludf.dummyfunction("""COMPUTED_VALUE"""),"Coordenador(a)") | G7: =IFERROR(__xludf.dummyfunction("""COMPUTED_VALUE"""),"Administrativo") | H7: =IFERROR(__xludf.dummyfunction("""COMPUTED_VALUE"""),"Gestão") | I7: #NAME? | J7: #NAME? | K7: #NAME? | L7: #NAME? | M7: #NAME? | N7: #NAME? | S7: #NAME? | T7: #NAME? | U7: #NAME? | V7: #NAME? | W7: #NAME? | X7: #NAME? | Y7: 0 | Z7: Não | AA7: 0 | AB7: Baixa | AD7: {=IFERROR(ifs( F7 = "Secretário(a)", INDEX(Secretario, MATCH(RIGHT(AC7), premissas_nivel_cargo_letra, 0), MATCH(VALUE(LEFT(AC7)), premissas_nivel_cargo_numero, 0)), F7 = "Presidente", INDEX(Presidente, MATCH(RIGHT(AC7), premissas_nivel_cargo_letra, 0), MATCH(VALUE(LEFT(AC7)), premissas_nivel_cargo_numero, 0)), F7 = "Subsecretário(a)", INDEX(Subsecretario, MATCH(RIGHT(AC7), premissas_nivel_cargo_letra, 0), MATCH(VALUE(LEFT(AC7)), premissas_nivel_cargo_numero, 0)), F7 = "Superintendente", INDEX(Superintendente, MATCH(RIGHT(AC7), premissas_nivel_cargo_letra, 0), MATCH(VALUE(LEFT(AC7)), premissas_nivel_cargo_numero, 0)), F7 = "Coordenador(a)", INDEX(Coordenador, MATCH(RIGHT(AC7), premissas_nivel_cargo_letra, 0), MATCH(VALUE(LEFT(AC7)), premissas_nivel_cargo_numero, 0)), F7 = "Chefe", INDEX(Chefe, MATCH(RIGHT(AC7), premissas_nivel_cargo_letra, 0), MATCH(VALUE(LEFT(AC7)), premissas_nivel_cargo_numero, 0)), F7 = "Diretor(a)", INDEX(Diretor, MATCH(RIGHT(AC7), premissas_nivel_cargo_letra, 0), MATCH(VALUE(LEFT(AC7)), premissas_nivel_cargo_numero, 0)), F7 = "Gerente", INDEX(Gerente, MATCH(RIGHT(AC7), premissas_nivel_cargo_letra, 0), MATCH(VALUE(LEFT(AC7)), premissas_nivel_cargo_numero, 0)), F7 = "Assessor(a)", INDEX(Assessor, MATCH(RIGHT(AC7), premissas_nivel_cargo_letra, 0), MATCH(VALUE(LEFT(AC7)), premissas_nivel_cargo_numero, 0)), F7 = "Ouvidor(a)", INDEX(Ouvidor, MATCH(RIGHT(AC7), premissas_nivel_cargo_letra, 0), MATCH(VALUE(LEFT(AC7)), premissas_nivel_cargo_numero, 0)) ), "")} | AE7: =ifs(G7 = "", "", AD7 = "", "Ainda Não Classificado", NOT(AD7 = ""), "Classificado com Sucesso")
A8: =IFERROR(__xludf.dummyfunction("""COMPUTED_VALUE"""),7) | B8: =IFERROR(__xludf.dummyfunction("""COMPUTED_VALUE"""),"SMDE") | C8: =IFERROR(__xludf.dummyfunction("""COMPUTED_VALUE"""),"1º") | D8: =IFERROR(__xludf.dummyfunction("""COMPUTED_VALUE"""),"Secretaria Municipal de Desenvolvimento Econômico") | E8: =IFERROR(__xludf.dummyfunction("""COMPUTED_VALUE"""),"Secretário Municipal") | F8: =IFERROR(__xludf.dummyfunction("""COMPUTED_VALUE"""),"Secretário(a)") | G8: =IFERROR(__xludf.dummyfunction("""COMPUTED_VALUE"""),"Administrativo") | H8: =IFERROR(__xludf.dummyfunction("""COMPUTED_VALUE"""),"Planejamento Urbano e Econômico") | I8: #NAME? | J8: #NAME? | K8: #NAME? | L8: #NAME? | M8: #NAME? | N8: #NAME? | S8: #NAME? | T8: #NAME? | U8: #NAME? | V8: #NAME? | W8: #NAME? | X8: #NAME? | Y8: 0 | Z8: Não | AA8: 0 | AB8: Baixa | AD8: {=IFERROR(ifs( F8 = "Secretário(a)", INDEX(Secretario, MATCH(RIGHT(AC8), premissas_nivel_cargo_letra, 0), MATCH(VALUE(LEFT(AC8)), premissas_nivel_cargo_numero, 0)), F8 = "Presidente", INDEX(Presidente, MATCH(RIGHT(AC8), premissas_nivel_cargo_letra, 0), MATCH(VALUE(LEFT(AC8)), premissas_nivel_cargo_numero, 0)), F8 = "Subsecretário(a)", INDEX(Subsecretario, MATCH(RIGHT(AC8), premissas_nivel_cargo_letra, 0), MATCH(VALUE(LEFT(AC8)), premissas_nivel_cargo_numero, 0)), F8 = "Superintendente", INDEX(Superintendente, MATCH(RIGHT(AC8), premissas_nivel_cargo_letra, 0), MATCH(VALUE(LEFT(AC8)), premissas_nivel_cargo_numero, 0)), F8 = "Coordenador(a)", INDEX(Coordenador, MATCH(RIGHT(AC8), premissas_nivel_cargo_letra, 0), MATCH(VALUE(LEFT(AC8)), premissas_nivel_cargo_numero, 0)), F8 = "Chefe", INDEX(Chefe, MATCH(RIGHT(AC8), premissas_nivel_cargo_letra, 0), MATCH(VALUE(LEFT(AC8)), premissas_nivel_cargo_numero, 0)), F8 = "Diretor(a)", INDEX(Diretor, MATCH(RIGHT(AC8), premissas_nivel_cargo_letra, 0), MATCH(VALUE(LEFT(AC8)), premissas_nivel_cargo_numero, 0)), F8 = "Gerente", INDEX(Gerente, MATCH(RIGHT(AC8), premissas_nivel_cargo_letra, 0), MATCH(VALUE(LEFT(AC8)), premissas_nivel_cargo_numero, 0)), F8 = "Assessor(a)", INDEX(Assessor, MATCH(RIGHT(AC8), premissas_nivel_cargo_letra, 0), MATCH(VALUE(LEFT(AC8)), premissas_nivel_cargo_numero, 0)), F8 = "Ouvidor(a)", INDEX(Ouvidor, MATCH(RIGHT(AC8), premissas_nivel_cargo_letra, 0), MATCH(VALUE(LEFT(AC8)), premissas_nivel_cargo_numero, 0)) ), "")} | AE8: =ifs(G8 = "", "", AD8 = "", "Ainda Não Classificado", NOT(AD8 = ""), "Classificado com Sucesso")
A9: =IFERROR(__xludf.dummyfunction("""COMPUTED_VALUE"""),8) | B9: =IFERROR(__xludf.dummyfunction("""COMPUTED_VALUE"""),"SMDE") | C9: =IFERROR(__xludf.dummyfunction("""COMPUTED_VALUE"""),"2º") | D9: =IFERROR(__xludf.dummyfunction("""COMPUTED_VALUE"""),"Chefia de Gabinete") | E9: =IFERROR(__xludf.dummyfunction("""COMPUTED_VALUE"""),"Chefe de Gabinete") | F9: =IFERROR(__xludf.dummyfunction("""COMPUTED_VALUE"""),"Chefe") | G9: =IFERROR(__xludf.dummyfunction("""COMPUTED_VALUE"""),"Administrativo") | H9: =IFERROR(__xludf.dummyfunction("""COMPUTED_VALUE"""),"Planejamento Urbano e Econômico") | I9: #NAME? | J9: #NAME? | K9: #NAME? | L9: #NAME? | M9: #NAME? | N9: #NAME? | S9: #NAME? | T9: #NAME? | U9: #NAME? | V9: #NAME? | W9: #NAME? | X9: #NAME? | Y9: 0 | Z9: Não | AA9: 0 | AB9: Baixa | AD9: {=IFERROR(ifs( F9 = "Secretário(a)", INDEX(Secretario, MATCH(RIGHT(AC9), premissas_nivel_cargo_letra, 0), MATCH(VALUE(LEFT(AC9)), premissas_nivel_cargo_numero, 0)), F9 = "Presidente", INDEX(Presidente, MATCH(RIGHT(AC9), premissas_nivel_cargo_letra, 0), MATCH(VALUE(LEFT(AC9)), premissas_nivel_cargo_numero, 0)), F9 = "Subsecretário(a)", INDEX(Subsecretario, MATCH(RIGHT(AC9), premissas_nivel_cargo_letra, 0), MATCH(VALUE(LEFT(AC9)), premissas_nivel_cargo_numero, 0)), F9 = "Superintendente", INDEX(Superintendente, MATCH(RIGHT(AC9), premissas_nivel_cargo_letra, 0), MATCH(VALUE(LEFT(AC9)), premissas_nivel_cargo_numero, 0)), F9 = "Coordenador(a)", INDEX(Coordenador, MATCH(RIGHT(AC9), premissas_nivel_cargo_letra, 0), MATCH(VALUE(LEFT(AC9)), premissas_nivel_cargo_numero, 0)), F9 = "Chefe", INDEX(Chefe, MATCH(RIGHT(AC9), premissas_nivel_cargo_letra, 0), MATCH(VALUE(LEFT(AC9)), premissas_nivel_cargo_numero, 0)), F9 = "Diretor(a)", INDEX(Diretor, MATCH(RIGHT(AC9), premissas_nivel_cargo_letra, 0), MATCH(VALUE(LEFT(AC9)), premissas_nivel_cargo_numero, 0)), F9 = "Gerente", INDEX(Gerente, MATCH(RIGHT(AC9), premissas_nivel_cargo_letra, 0), MATCH(VALUE(LEFT(AC9)), premissas_nivel_cargo_numero, 0)), F9 = "Assessor(a)", INDEX(Assessor, MATCH(RIGHT(AC9), premissas_nivel_cargo_letra, 0), MATCH(VALUE(LEFT(AC9)), premissas_nivel_cargo_numero, 0)), F9 = "Ouvidor(a)", INDEX(Ouvidor, MATCH(RIGHT(AC9), premissas_nivel_cargo_letra, 0), MATCH(VALUE(LEFT(AC9)), premissas_nivel_cargo_numero, 0)) ), "")} | AE9: =ifs(G9 = "", "", AD9 = "", "Ainda Não Classificado", NOT(AD9 = ""), "Classificado com Sucesso")
A10: =IFERROR(__xludf.dummyfunction("""COMPUTED_VALUE"""),9) | B10: =IFERROR(__xludf.dummyfunction("""COMPUTED_VALUE"""),"SMDE") | C10: =IFERROR(__xludf.dummyfunction("""COMPUTED_VALUE"""),"2º") | D10: =IFERROR(__xludf.dummyfunction("""COMPUTED_VALUE"""),"Subsecretaria de Desenvolvimento Econômico e Inovação") | E10: =IFERROR(__xludf.dummyfunction("""COMPUTED_VALUE"""),"Subsecretário") | F10: =IFERROR(__xludf.dummyfunction("""COMPUTED_VALUE"""),"Subsecretário(a)") | G10: =IFERROR(__xludf.dummyfunction("""COMPUTED_VALUE"""),"Técnico-Operacional") | H10: =IFERROR(__xludf.dummyfunction("""COMPUTED_VALUE"""),"Planejamento Urbano e Econômico") | I10: #NAME? | J10: #NAME? | K10: #NAME? | L10: #NAME? | M10: #NAME? | N10: #NAME? | S10: #NAME? | T10: #NAME? | U10: #NAME? | V10: #NAME? | W10: #NAME? | X10: #NAME? | Y10: 0 | Z10: Não | AA10: 0 | AB10: Baixa | AD10: {=IFERROR(ifs( F10 = "Secretário(a)", INDEX(Secretario, MATCH(RIGHT(AC10), premissas_nivel_cargo_letra, 0), MATCH(VALUE(LEFT(AC10)), premissas_nivel_cargo_numero, 0)), F10 = "Presidente", INDEX(Presidente, MATCH(RIGHT(AC10), premissas_nivel_cargo_letra, 0), MATCH(VALUE(LEFT(AC10)), premissas_nivel_cargo_numero, 0)), F10 = "Subsecretário(a)", INDEX(Subsecretario, MATCH(RIGHT(AC10), premissas_nivel_cargo_letra, 0), MATCH(VALUE(LEFT(AC10)), premissas_nivel_cargo_numero, 0)), F10 = "Superintendente", INDEX(Superintendente, MATCH(RIGHT(AC10), premissas_nivel_cargo_letra, 0), MATCH(VALUE(LEFT(AC10)), premissas_nivel_cargo_numero, 0)), F10 = "Coordenador(a)", INDEX(Coordenador, MATCH(RIGHT(AC10), premissas_nivel_cargo_letra, 0), MATCH(VALUE(LEFT(AC10)), premissas_nivel_cargo_numero, 0)), F10 = "Chefe", INDEX(Chefe, MATCH(RIGHT(AC10), premissas_nivel_cargo_letra, 0), MATCH(VALUE(LEFT(AC10)), premissas_nivel_cargo_numero, 0)), F10 = "Diretor(a)", INDEX(Diretor, MATCH(RIGHT(AC10), premissas_nivel_cargo_letra, 0), MATCH(VALUE(LEFT(AC10)), premissas_nivel_cargo_numero, 0)), F10 = "Gerente", INDEX(Gerente, MATCH(RIGHT(AC10), premissas_nivel_cargo_letra, 0), MATCH(VALUE(LEFT(AC10)), premissas_nivel_cargo_numero, 0)), F10 = "Assessor(a)", INDEX(Assessor, MATCH(RIGHT(AC10), premissas_nivel_cargo_letra, 0), MATCH(VALUE(LEFT(AC10)), premissas_nivel_cargo_numero, 0)), F10 = "Ouvidor(a)", INDEX(Ouvidor, MATCH(RIGHT(AC10), premissas_nivel_cargo_letra, 0), MATCH(VALUE(LEFT(AC10)), premissas_nivel_cargo_numero, 0)) ), "")} | AE10: =ifs(G10 = "", "", AD10 = "", "Ainda Não Classificado", NOT(AD10 = ""), "Classificado com Sucesso")
A11: =IFERROR(__xludf.dummyfunction("""COMPUTED_VALUE"""),10) | B11: =IFERROR(__xludf.dummyfunction("""COMPUTED_VALUE"""),"SMDE") | C11: =IFERROR(__xludf.dummyfunction("""COMPUTED_VALUE"""),"3º") | D11: =IFERROR(__xludf.dummyfunction("""COMPUTED_VALUE"""),"Escritório de Política Econômica") | E11: =IFERROR(__xludf.dummyfunction("""COMPUTED_VALUE"""),"Diretor I") | F11: =IFERROR(__xludf.dummyfunction("""COMPUTED_VALUE"""),"Diretor(a)") | G11: =IFERROR(__xludf.dummyfunction("""COMPUTED_VALUE"""),"Administrativo") | H11: =IFERROR(__xludf.dummyfunction("""COMPUTED_VALUE"""),"Planejamento Urbano e Econômico") | I11: #NAME? | J11: #NAME? | K11: #NAME? | L11: #NAME? | M11: #NAME? | N11: #NAME? | S11: #NAME? | T11: #NAME? | U11: #NAME? | V11: #NAME? | W11: #NAME? | X11: #NAME? | Y11: 0 | Z11: Não | AA11: 0 | AB11: Baixa | AD11: {=IFERROR(ifs( F11 = "Secretário(a)", INDEX(Secretario, MATCH(RIGHT(AC11), premissas_nivel_cargo_letra, 0), MATCH(VALUE(LEFT(AC11)), premissas_nivel_cargo_numero, 0)), F11 = "Presidente", INDEX(Presidente, MATCH(RIGHT(AC11), premissas_nivel_cargo_letra, 0), MATCH(VALUE(LEFT(AC11)), premissas_nivel_cargo_numero, 0)), F11 = "Subsecretário(a)", INDEX(Subsecretario, MATCH(RIGHT(AC11), premissas_nivel_cargo_letra, 0), MATCH(VALUE(LEFT(AC11)), premissas_nivel_cargo_numero, 0)), F11 = "Superintendente", INDEX(Superintendente, MATCH(RIGHT(AC11), premissas_nivel_cargo_letra, 0), MATCH(VALUE(LEFT(AC11)), premissas_nivel_cargo_numero, 0)), F11 = "Coordenador(a)", INDEX(Coordenador, MATCH(RIGHT(AC11), premissas_nivel_cargo_letra, 0), MATCH(VALUE(LEFT(AC11)), premissas_nivel_cargo_numero, 0)), F11 = "Chefe", INDEX(Chefe, MATCH(RIGHT(AC11), premissas_nivel_cargo_letra, 0), MATCH(VALUE(LEFT(AC11)), premissas_nivel_cargo_numero, 0)), F11 = "Diretor(a)", INDEX(Diretor, MATCH(RIGHT(AC11), premissas_nivel_cargo_letra, 0), MATCH(VALUE(LEFT(AC11)), premissas_nivel_cargo_numero, 0)), F11 = "Gerente", INDEX(Gerente, MATCH(RIGHT(AC11), premissas_nivel_cargo_letra, 0), MATCH(VALUE(LEFT(AC11)), premissas_nivel_cargo_numero, 0)), F11 = "Assessor(a)", INDEX(Assessor, MATCH(RIGHT(AC11), premissas_nivel_cargo_letra, 0), MATCH(VALUE(LEFT(AC11)), premissas_nivel_cargo_numero, 0)), F11 = "Ouvidor(a)", INDEX(Ouvidor, MATCH(RIGHT(AC11), premissas_nivel_cargo_letra, 0), MATCH(VALUE(LEFT(AC11)), premissas_nivel_cargo_numero, 0)) ), "")} | AE11: =ifs(G11 = "", "", AD11 = "", "Ainda Não Classificado", NOT(AD11 = ""), "Classificado com Sucesso")
A12: =IFERROR(__xludf.dummyfunction("""COMPUTED_VALUE"""),11) | B12: =IFERROR(__xludf.dummyfunction("""COMPUTED_VALUE"""),"SMDE") | C12: =IFERROR(__xludf.dummyfunction("""COMPUTED_VALUE"""),"3º") | D12: =IFERROR(__xludf.dummyfunction("""COMPUTED_VALUE"""),"Escritório de Monitoramento e Processamento de Dados") | E12: =IFERROR(__xludf.dummyfunction("""COMPUTED_VALUE"""),"Diretor I") | F12: =IFERROR(__xludf.dummyfunction("""COMPUTED_VALUE"""),"Diretor(a)") | G12: =IFERROR(__xludf.dummyfunction("""COMPUTED_VALUE"""),"Técnico-Operacional") | H12: =IFERROR(__xludf.dummyfunction("""COMPUTED_VALUE"""),"Planejamento Urbano e Econômico") | I12: #NAME? | J12: #NAME? | K12: #NAME? | L12: #NAME? | M12: #NAME? | N12: #NAME? | S12: #NAME? | T12: #NAME? | U12: #NAME? | V12: #NAME? | W12: #NAME? | X12: #NAME? | Y12: 0 | Z12: Não | AA12: 0 | AB12: Baixa | AD12: {=IFERROR(ifs( F12 = "Secretário(a)", INDEX(Secretario, MATCH(RIGHT(AC12), premissas_nivel_cargo_letra, 0), MATCH(VALUE(LEFT(AC12)), premissas_nivel_cargo_numero, 0)), F12 = "Presidente", INDEX(Presidente, MATCH(RIGHT(AC12), premissas_nivel_cargo_letra, 0), MATCH(VALUE(LEFT(AC12)), premissas_nivel_cargo_numero, 0)), F12 = "Subsecretário(a)", INDEX(Subsecretario, MATCH(RIGHT(AC12), premissas_nivel_cargo_letra, 0), MATCH(VALUE(LEFT(AC12)), premissas_nivel_cargo_numero, 0)), F12 = "Superintendente", INDEX(Superintendente, MATCH(RIGHT(AC12), premissas_nivel_cargo_letra, 0), MATCH(VALUE(LEFT(AC12)), premissas_nivel_cargo_numero, 0)), F12 = "Coordenador(a)", INDEX(Coordenador, MATCH(RIGHT(AC12), premissas_nivel_cargo_letra, 0), MATCH(VALUE(LEFT(AC12)), premissas_nivel_cargo_numero, 0)), F12 = "Chefe", INDEX(Chefe, MATCH(RIGHT(AC12), premissas_nivel_cargo_letra, 0), MATCH(VALUE(LEFT(AC12)), premissas_nivel_cargo_numero, 0)), F12 = "Diretor(a)", INDEX(Diretor, MATCH(RIGHT(AC12), premissas_nivel_cargo_letra, 0), MATCH(VALUE(LEFT(AC12)), premissas_nivel_cargo_numero, 0)), F12 = "Gerente", INDEX(Gerente, MATCH(RIGHT(AC12), premissas_nivel_cargo_letra, 0), MATCH(VALUE(LEFT(AC12)), premissas_nivel_cargo_numero, 0)), F12 = "Assessor(a)", INDEX(Assessor, MATCH(RIGHT(AC12), premissas_nivel_cargo_letra, 0), MATCH(VALUE(LEFT(AC12)), premissas_nivel_cargo_numero, 0)), F12 = "Ouvidor(a)", INDEX(Ouvidor, MATCH(RIGHT(AC12), premissas_nivel_cargo_letra, 0), MATCH(VALUE(LEFT(AC12)), premissas_nivel_cargo_numero, 0)) ), "")} | AE12: =ifs(G12 = "", "", AD12 = "", "Ainda Não Classificado", NOT(AD12 = ""), "Classificado com Sucesso")
A13: =IFERROR(__xludf.dummyfunction("""COMPUTED_VALUE"""),12) | B13: =IFERROR(__xludf.dummyfunction("""COMPUTED_VALUE"""),"SMDE") | C13: =IFERROR(__xludf.dummyfunction("""COMPUTED_VALUE"""),"2º") | D13: =IFERROR(__xludf.dummyfunction("""COMPUTED_VALUE"""),"Subsecretaria de Regulação e Ambiente de Negócios") | E13: =IFERROR(__xludf.dummyfunction("""COMPUTED_VALUE"""),"Subsecretário") | F13: =IFERROR(__xludf.dummyfunction("""COMPUTED_VALUE"""),"Subsecretário(a)") | G13: =IFERROR(__xludf.dummyfunction("""COMPUTED_VALUE"""),"Técnico-Operacional") | H13: =IFERROR(__xludf.dummyfunction("""COMPUTED_VALUE"""),"Planejamento Urbano e Econômico") | I13: #NAME? | J13: #NAME? | K13: #NAME? | L13: #NAME? | M13: #NAME? | N13: #NAME? | S13: #NAME? | T13: #NAME? | U13: #NAME? | V13: #NAME? | W13: #NAME? | X13: #NAME? | Y13: 0 | Z13: Não | AA13: 0 | AB13: Baixa | AD13: {=IFERROR(ifs( F13 = "Secretário(a)", INDEX(Secretario, MATCH(RIGHT(AC13), premissas_nivel_cargo_letra, 0), MATCH(VALUE(LEFT(AC13)), premissas_nivel_cargo_numero, 0)), F13 = "Presidente", INDEX(Presidente, MATCH(RIGHT(AC13), premissas_nivel_cargo_letra, 0), MATCH(VALUE(LEFT(AC13)), premissas_nivel_cargo_numero, 0)), F13 = "Subsecretário(a)", INDEX(Subsecretario, MATCH(RIGHT(AC13), premissas_nivel_cargo_letra, 0), MATCH(VALUE(LEFT(AC13)), premissas_nivel_cargo_numero, 0)), F13 = "Superintendente", INDEX(Superintendente, MATCH(RIGHT(AC13), premissas_nivel_cargo_letra, 0), MATCH(VALUE(LEFT(AC13)), premissas_nivel_cargo_numero, 0)), F13 = "Coordenador(a)", INDEX(Coordenador, MATCH(RIGHT(AC13), premissas_nivel_cargo_letra, 0), MATCH(VALUE(LEFT(AC13)), premissas_nivel_cargo_numero, 0)), F13 = "Chefe", INDEX(Chefe, MATCH(RIGHT(AC13), premissas_nivel_cargo_letra, 0), MATCH(VALUE(LEFT(AC13)), premissas_nivel_cargo_numero, 0)), F13 = "Diretor(a)", INDEX(Diretor, MATCH(RIGHT(AC13), premissas_nivel_cargo_letra, 0), MATCH(VALUE(LEFT(AC13)), premissas_nivel_cargo_numero, 0)), F13 = "Gerente", INDEX(Gerente, MATCH(RIGHT(AC13), premissas_nivel_cargo_letra, 0), MATCH(VALUE(LEFT(AC13)), premissas_nivel_cargo_numero, 0)), F13 = "Assessor(a)", INDEX(Assessor, MATCH(RIGHT(AC13), premissas_nivel_cargo_letra, 0), MATCH(VALUE(LEFT(AC13)), premissas_nivel_cargo_numero, 0)), F13 = "Ouvidor(a)", INDEX(Ouvidor, MATCH(RIGHT(AC13), premissas_nivel_cargo_letra, 0), MATCH(VALUE(LEFT(AC13)), premissas_nivel_cargo_numero, 0)) ), "")} | AE13: =ifs(G13 = "", "", AD13 = "", "Ainda Não Classificado", NOT(AD13 = ""), "Classificado com Sucesso")
